<robot name="fetch_arm">
  <link name="base">
    <inertial>
      <origin rpy="0 0 0" xyz="0 0 0" />
      <mass value="0" />
      <inertia ixx="0" ixy="0.0" ixz="0" iyy="0" iyz="0" izz="0" />
    </inertial>
  </link>
  <joint name="shoulder_pan_joint" type="revolute">
    <origin rpy="0 0 0" xyz="0 0 0" />
    <parent link="base" />
    <child link="shoulder_pan_link" />
    <axis xyz="0 0 1" />
    <dynamics damping="1.0" />
    <limit effort="33.82" lower="-1.6056" upper="1.6056" velocity="1.256" />
  </joint>
  <link name="shoulder_pan_link">
    <inertial>
      <origin rpy="0 0 0" xyz="0.0927 -0.0056 0.0564" />
      <mass value="2.5587" />
      <inertia ixx="0.0043" ixy="-0.0001" ixz="0.001" iyy="0.0087" iyz="-0.0001" izz="0.0087" />
    </inertial>
    <visual>
      <origin rpy="0 0 0" xyz="0 0 0" />
      <geometry>
        <mesh filename="package://fetch_description/meshes/shoulder_pan_link.dae" />
      </geometry>
      <material name="">
        <color rgba="1 1 1 1" />
      </material>
    </visual>
  </link>
  <joint name="shoulder_lift_joint" type="revolute">
    <origin rpy="0 0 0" xyz="0.117 0 0.0599999999999999" />
    <parent link="shoulder_pan_link" />
    <child link="shoulder_lift_link" />
    <axis xyz="0 1 0" />
    <dynamics damping="1.0" />
    <limit effort="131.76" lower="-1.221" upper="1.518" velocity="1.454" />
  </joint>
  <link name="shoulder_lift_link">
    <inertial>
      <origin rpy="0 0 0" xyz="0.1432 0.0072 -0.0001" />
      <mass value="2.6615" />
      <inertia ixx="0.0028" ixy="-0.0021" ixz="-0.0" iyy="0.0111" iyz="-0.0" izz="0.0112" />
    </inertial>
    <visual>
      <origin rpy="0 0 0" xyz="0 0 0" />
      <geometry>
        <mesh filename="package://fetch_description/meshes/shoulder_lift_link.dae" />
      </geometry>
      <material name="">
        <color rgba="0.086 0.506 0.767 1" />
      </material>
    </visual>
  </link>
  <joint name="upperarm_roll_joint" type="continuous">
    <origin rpy="0 0 0" xyz="0.219 0 0" />
    <parent link="shoulder_lift_link" />
    <child link="upperarm_roll_link" />
    <axis xyz="1 0 0" />
    <dynamics damping="5.0" />
    <limit effort="76.94" velocity="1.571" />
  </joint>
  <link name="upperarm_roll_link">
    <inertial>
      <origin rpy="0 0 0" xyz="0.1165 0.0014 0.0000" />
      <mass value="2.3311" />
      <inertia ixx="0.0019" ixy="-0.0001" ixz="0.0" iyy="0.0045" iyz="0.0" izz="0.0047" />
    </inertial>
    <visual>
      <origin rpy="0 0 0" xyz="0 0 0" />
      <geometry>
        <mesh filename="package://fetch_description/meshes/upperarm_roll_link.dae" />
      </geometry>
      <material name="">
        <color rgba="1 1 1 1" />
      </material>
    </visual>
  </link>
  <joint name="elbow_flex_joint" type="revolute">
    <origin rpy="0 0 0" xyz="0.133 0 0" />
    <parent link="upperarm_roll_link" />
    <child link="elbow_flex_link" />
    <axis xyz="0 1 0" />
    <dynamics damping="1.0" />
    <limit effort="66.18" lower="-2.251" upper="2.251" velocity="1.521" />
  </joint>
  <link name="elbow_flex_link">
    <inertial>
      <origin rpy="0 0 0" xyz="0.1279 0.0073 0.0000" />
      <mass value="2.1299" />
      <inertia ixx="0.0024" ixy="-0.0016" ixz="0.0" iyy="0.0082" iyz="-0.0" izz="0.0084" />
    </inertial>
    <visual>
      <origin rpy="0 0 0" xyz="0 0 0" />
      <geometry>
        <mesh filename="package://fetch_description/meshes/elbow_flex_link.dae" />
      </geometry>
      <material name="">
        <color rgba="0.086 0.506 0.767 1" />
      </material>
    </visual>
  </link>
  <joint name="forearm_roll_joint" type="continuous">
    <origin rpy="0 0 0" xyz="0.197 0 0" />
    <parent link="elbow_flex_link" />
    <child link="forearm_roll_link" />
    <axis xyz="1 0 0" />
    <dynamics damping="5.0" />
    <limit effort="29.35" velocity="1.571" />
  </joint>
  <link name="forearm_roll_link">
    <inertial>
      <origin rpy="0 0 0" xyz="0.1097 -0.0266 0.0000" />
      <mass value="1.6563" />
      <inertia ixx="0.0016" ixy="-0.0003" ixz="0.0" iyy="0.003" iyz="-0.0" izz="0.0035" />
    </inertial>
    <visual>
      <origin rpy="0 0 0" xyz="0 0 0" />
      <geometry>
        <mesh filename="package://fetch_description/meshes/forearm_roll_link.dae" />
      </geometry>
      <material name="">
        <color rgba="1 1 1 1" />
      </material>
    </visual>
  </link>
  <joint name="wrist_flex_joint" type="revolute">
    <origin rpy="0 0 0" xyz="0.1245 0 0" />
    <parent link="forearm_roll_link" />
    <child link="wrist_flex_link" />
    <axis xyz="0 1 0" />
    <dynamics damping="1.0" />
    <limit effort="25.7" lower="-2.16" upper="2.16" velocity="2.268" />
  </joint>
  <link name="wrist_flex_link">
    <inertial>
      <origin rpy="0 0 0" xyz="0.1542 4.1128e-04 -7.8568e-04" />
      <mass value="3.5375" />
      <inertia ixx="0.007241034025706" ixy="0.000012004117677" ixz="0.000145196501142" iyy="0.022483723331150" iyz="-0.000001234981342" izz="0.023020308182417" />
    </inertial>
    <visual>
      <origin rpy="0 0 0" xyz="0 0 0" />
      <geometry>
        <mesh filename="package://fetch_description/meshes/wrist_flex_link.dae" />
      </geometry>
      <material name="">
        <color rgba="0.086 0.506 0.767 1" />
      </material>
    </visual>
  </link>
  <joint name="end_effector_position" type="revolute">
    <origin rpy="0 0 0" xyz="0.3302 0 0" />
    <parent link="wrist_flex_link" />
    <child link="some_end_effector" />
    <axis xyz="0 1 0" />
    <dynamics damping="0.0" />
    <limit effort="25.7" lower="-2.16" upper="2.16" velocity="2.268" />
  </joint>
  <link name="some_end_effector">
    <inertial>
      <origin rpy="0 0 0" xyz="0 0 0" />
      <mass value="1.0" />
      <inertia ixx="0.007241034025706" ixy="0.000012004117677" ixz="0.000145196501142" iyy="0.022483723331150" iyz="-0.000001234981342" izz="0.023020308182417" />
    </inertial>
    <visual>
      <origin rpy="0 0 0" xyz="0 0 0" />
      <geometry>
        <mesh filename="package://fetch_description/meshes/wrist_flex_link.dae" />
      </geometry>
      <material name="">
        <color rgba="0.086 0.506 0.767 1" />
      </material>
    </visual>
  </link>
</robot>
